2024-05-21 18:30:41,341 INFO    StreamThr :10748 [internal.py:wandb_internal():86] W&B internal server running at pid: 10748, started at: 2024-05-21 18:30:41.340696
2024-05-21 18:30:41,344 DEBUG   HandlerThread:10748 [handler.py:handle_request():146] handle_request: status
2024-05-21 18:30:41,346 INFO    WriterThread:10748 [datastore.py:open_for_write():87] open: /home/minjae/Documents/Minjae/Research/minjae-rl/wandb/run-20240521_183041-bc85d964-f9b7-4bf6-8579-e4980206f940/run-bc85d964-f9b7-4bf6-8579-e4980206f940.wandb
2024-05-21 18:30:41,350 DEBUG   SenderThread:10748 [sender.py:send():379] send: header
2024-05-21 18:30:41,354 DEBUG   SenderThread:10748 [sender.py:send():379] send: run
2024-05-21 18:30:41,366 INFO    SenderThread:10748 [sender.py:_setup_resume():749] checking resume status for None/purpose/bc85d964-f9b7-4bf6-8579-e4980206f940
2024-05-21 18:30:45,070 INFO    SenderThread:10748 [retry.py:__call__():172] Retry attempt failed:
Traceback (most recent call last):
  File "/home/minjae/miniconda3/envs/rl/lib/python3.10/site-packages/urllib3/connection.py", line 174, in _new_conn
    conn = connection.create_connection(
  File "/home/minjae/miniconda3/envs/rl/lib/python3.10/site-packages/urllib3/util/connection.py", line 72, in create_connection
    for res in socket.getaddrinfo(host, port, family, socket.SOCK_STREAM):
  File "/home/minjae/miniconda3/envs/rl/lib/python3.10/socket.py", line 955, in getaddrinfo
    for res in _socket.getaddrinfo(host, port, family, type, proto, flags):
socket.gaierror: [Errno -3] Temporary failure in name resolution

During handling of the above exception, another exception occurred:

Traceback (most recent call last):
  File "/home/minjae/miniconda3/envs/rl/lib/python3.10/site-packages/urllib3/connectionpool.py", line 715, in urlopen
    httplib_response = self._make_request(
  File "/home/minjae/miniconda3/envs/rl/lib/python3.10/site-packages/urllib3/connectionpool.py", line 404, in _make_request
    self._validate_conn(conn)
  File "/home/minjae/miniconda3/envs/rl/lib/python3.10/site-packages/urllib3/connectionpool.py", line 1058, in _validate_conn
    conn.connect()
  File "/home/minjae/miniconda3/envs/rl/lib/python3.10/site-packages/urllib3/connection.py", line 363, in connect
    self.sock = conn = self._new_conn()
  File "/home/minjae/miniconda3/envs/rl/lib/python3.10/site-packages/urllib3/connection.py", line 186, in _new_conn
    raise NewConnectionError(
urllib3.exceptions.NewConnectionError: <urllib3.connection.HTTPSConnection object at 0x7661a9f346a0>: Failed to establish a new connection: [Errno -3] Temporary failure in name resolution

During handling of the above exception, another exception occurred:

Traceback (most recent call last):
  File "/home/minjae/.local/lib/python3.10/site-packages/requests/adapters.py", line 486, in send
    resp = conn.urlopen(
  File "/home/minjae/miniconda3/envs/rl/lib/python3.10/site-packages/urllib3/connectionpool.py", line 799, in urlopen
    retries = retries.increment(
  File "/home/minjae/miniconda3/envs/rl/lib/python3.10/site-packages/urllib3/util/retry.py", line 592, in increment
    raise MaxRetryError(_pool, url, error or ResponseError(cause))
urllib3.exceptions.MaxRetryError: HTTPSConnectionPool(host='api.wandb.ai', port=443): Max retries exceeded with url: /graphql (Caused by NewConnectionError('<urllib3.connection.HTTPSConnection object at 0x7661a9f346a0>: Failed to establish a new connection: [Errno -3] Temporary failure in name resolution'))

During handling of the above exception, another exception occurred:

Traceback (most recent call last):
  File "/home/minjae/miniconda3/envs/rl/lib/python3.10/site-packages/wandb/sdk/lib/retry.py", line 131, in __call__
    result = self._call_fn(*args, **kwargs)
  File "/home/minjae/miniconda3/envs/rl/lib/python3.10/site-packages/wandb/sdk/internal/internal_api.py", line 369, in execute
    return self.client.execute(*args, **kwargs)  # type: ignore
  File "/home/minjae/miniconda3/envs/rl/lib/python3.10/site-packages/wandb/vendor/gql-0.2.0/wandb_gql/client.py", line 52, in execute
    result = self._get_result(document, *args, **kwargs)
  File "/home/minjae/miniconda3/envs/rl/lib/python3.10/site-packages/wandb/vendor/gql-0.2.0/wandb_gql/client.py", line 60, in _get_result
    return self.transport.execute(document, *args, **kwargs)
  File "/home/minjae/miniconda3/envs/rl/lib/python3.10/site-packages/wandb/sdk/lib/gql_request.py", line 58, in execute
    request = self.session.post(self.url, **post_args)
  File "/home/minjae/.local/lib/python3.10/site-packages/requests/sessions.py", line 637, in post
    return self.request("POST", url, data=data, json=json, **kwargs)
  File "/home/minjae/.local/lib/python3.10/site-packages/requests/sessions.py", line 589, in request
    resp = self.send(prep, **send_kwargs)
  File "/home/minjae/.local/lib/python3.10/site-packages/requests/sessions.py", line 703, in send
    r = adapter.send(request, **kwargs)
  File "/home/minjae/.local/lib/python3.10/site-packages/requests/adapters.py", line 519, in send
    raise ConnectionError(e, request=request)
requests.exceptions.ConnectionError: HTTPSConnectionPool(host='api.wandb.ai', port=443): Max retries exceeded with url: /graphql (Caused by NewConnectionError('<urllib3.connection.HTTPSConnection object at 0x7661a9f346a0>: Failed to establish a new connection: [Errno -3] Temporary failure in name resolution'))
2024-05-21 18:30:46,356 DEBUG   HandlerThread:10748 [handler.py:handle_request():146] handle_request: keepalive
2024-05-21 18:30:51,358 DEBUG   HandlerThread:10748 [handler.py:handle_request():146] handle_request: keepalive
2024-05-21 18:30:56,359 DEBUG   HandlerThread:10748 [handler.py:handle_request():146] handle_request: keepalive
2024-05-21 18:31:01,361 DEBUG   HandlerThread:10748 [handler.py:handle_request():146] handle_request: keepalive
